<?xml version="1.0" ?>
<!-- =================================================================================== -->
<!-- |    This document was autogenerated by xacro from assignment3.xacro              | -->
<!-- |    EDITING THIS FILE BY HAND IS NOT RECOMMENDED                                 | -->
<!-- =================================================================================== -->
<robot name="robot">
  <!-- world -->
  <link name="world"/>
  <!-- Links -->
  <link name="world_interface"/>
  <link name="workcell">
    <visual>
      <geometry>
        <mesh filename="package://ros_industrial_support/meshes/workcell/visual/workcell.dae"/>
      </geometry>
    </visual>
    <collision>
      <geometry>
        <mesh filename="package://ros_industrial_support/meshes/workcell/collision/workcell.dae"/>
      </geometry>
    </collision>
    <inertial>
      <inertia ixx="1.0" ixy="0" ixz="0" iyy="1.0" iyz="0" izz="1.0"/>
      <mass value="100"/>
    </inertial>
  </link>
  <joint name="workcell_to_world_interface" type="fixed">
    <parent link="world_interface"/>
    <child link="workcell"/>
    <origin rpy="0 0 1.5707963267948966" xyz="0 0 0"/>
  </joint>
  <joint name="robot1_pedestal_joint" type="fixed">
    <origin rpy="0 0 0" xyz="0.5 1.8 0.0"/>
    <parent link="world_interface"/>
    <child link="robot1_pedestal_link"/>
  </joint>
  <link name="robot1_pedestal_link">
    <visual>
      <origin xyz="0 0 0.475"/>
      <geometry>
        <box size="0.3 0.3 0.95"/>
      </geometry>
      <material name="pedestal_color">
        <color rgba="0 0.1568627450980392 0.5254901960784314 1"/>
      </material>
    </visual>
    <collision>
      <origin xyz="0 0 0.475"/>
      <geometry>
        <box size="0.3 0.3 0.95"/>
      </geometry>
    </collision>
    <inertial>
      <mass value="500"/>
      <origin rpy="0 0 0" xyz="0 0 0"/>
      <inertia ixx="0.001" ixy="0" ixz="0" iyy="0.001" iyz="0" izz="0.001"/>
    </inertial>
  </link>
  <gazebo reference="robot1_pedestal_link">
    <material>Gazebo/Blue</material>
  </gazebo>
  <!--
  <xacro:arg name="prefix" default="arm_"/>
  <xacro:arg name="hw_ns" default="xarm"/>
  -->
  <!-- Insert at the beginning of xarm_device_macro.xacro -->
  <material name="robot1_Black">
    <color rgba="0.0 0.0 0.0 1.0"/>
  </material>
  <material name="robot1_Red">
    <color rgba="0.8 0.0 0.0 1.0"/>
  </material>
  <material name="robot1_White">
    <color rgba="1.0 1.0 1.0 1.0"/>
  </material>
  <material name="robot1_Silver">
    <color rgba="0.753 0.753 0.753 1.0"/>
  </material>
  <joint name="robot1_world_joint" type="fixed">
    <parent link="robot1_xarm_link"/>
    <child link="robot1_link_base"/>
    <origin rpy="0 0 0" xyz="0 0 0"/>
  </joint>
  <ros2_control name="robot1_uf_robot_hardware/UFRobotSystemHardware" type="system">
    <hardware>
      <plugin>uf_robot_hardware/UFRobotSystemHardware</plugin>
      <param name="hw_ns">robot1_</param>
      <param name="velocity_control">False</param>
      <param name="prefix">Probot1_</param>
      <param name="robot_ip">R</param>
      <param name="report_type">normal</param>
      <param name="dof">6</param>
      <param name="baud_checkset">True</param>
      <param name="default_gripper_baud">2000000</param>
      <param name="robot_type">xarm</param>
      <param name="add_gripper">False</param>
      <param name="add_bio_gripper">False</param>
      <!-- fake -->
      <!-- <plugin>fake_components/GenericSystem</plugin> -->
      <!-- gazebo -->
      <!-- <plugin>gazebo_ros2_control/GazeboSystem</plugin> -->
      <!-- real xarm -->
      <!-- <plugin>uf_robot_hardware/UFRobotSystemHardware</plugin> -->
    </hardware>
    <joint name="robot1_joint1">
      <command_interface name="position">
        <param name="min">-6.283185307179586</param>
        <param name="max">6.283185307179586</param>
      </command_interface>
      <command_interface name="velocity">
        <param name="min">-3.14</param>
        <param name="max">3.14</param>
      </command_interface>
      <state_interface name="position"/>
      <state_interface name="velocity"/>
      <!-- <state_interface name="effort"/> -->
    </joint>
    <joint name="robot1_joint2">
      <command_interface name="position">
        <param name="min">-2.059</param>
        <param name="max">2.0944</param>
      </command_interface>
      <command_interface name="velocity">
        <param name="min">-3.14</param>
        <param name="max">3.14</param>
      </command_interface>
      <state_interface name="position"/>
      <state_interface name="velocity"/>
      <!-- <state_interface name="effort"/> -->
    </joint>
    <joint name="robot1_joint3">
      <command_interface name="position">
        <param name="min">-3.927</param>
        <param name="max">0.19198</param>
      </command_interface>
      <command_interface name="velocity">
        <param name="min">-3.14</param>
        <param name="max">3.14</param>
      </command_interface>
      <state_interface name="position"/>
      <state_interface name="velocity"/>
      <!-- <state_interface name="effort"/> -->
    </joint>
    <joint name="robot1_joint4">
      <command_interface name="position">
        <param name="min">-6.283185307179586</param>
        <param name="max">6.283185307179586</param>
      </command_interface>
      <command_interface name="velocity">
        <param name="min">-3.14</param>
        <param name="max">3.14</param>
      </command_interface>
      <state_interface name="position"/>
      <state_interface name="velocity"/>
      <!-- <state_interface name="effort"/> -->
    </joint>
    <joint name="robot1_joint5">
      <command_interface name="position">
        <param name="min">-1.69297</param>
        <param name="max">3.141592653589793</param>
      </command_interface>
      <command_interface name="velocity">
        <param name="min">-3.14</param>
        <param name="max">3.14</param>
      </command_interface>
      <state_interface name="position"/>
      <state_interface name="velocity"/>
      <!-- <state_interface name="effort"/> -->
    </joint>
    <joint name="robot1_joint6">
      <command_interface name="position">
        <param name="min">-6.283185307179586</param>
        <param name="max">6.283185307179586</param>
      </command_interface>
      <command_interface name="velocity">
        <param name="min">-3.14</param>
        <param name="max">3.14</param>
      </command_interface>
      <state_interface name="position"/>
      <state_interface name="velocity"/>
      <!-- <state_interface name="effort"/> -->
    </joint>
  </ros2_control>
  <link name="robot1_link_base">
    <inertial>
      <origin rpy="0 0 0" xyz="0.0 0.0 0.09103"/>
      <mass value="2.7"/>
      <inertia ixx="0.00494875" ixy="-3.5E-06" ixz="1.25E-05" iyy="0.00494174" iyz="1.67E-06" izz="0.002219"/>
    </inertial>
    <visual>
      <geometry>
        <mesh filename="package://xarm_description/meshes/xarm6/visual/link_base.stl"/>
      </geometry>
      <origin rpy="0 0 0" xyz="0 0 0"/>
      <material name="robot1_White"/>
    </visual>
    <collision>
      <geometry>
        <mesh filename="package://xarm_description/meshes/xarm6/visual/link_base.stl"/>
      </geometry>
      <origin rpy="0 0 0" xyz="0 0 0"/>
    </collision>
  </link>
  <link name="robot1_link1">
    <inertial>
      <origin rpy="0 0 0" xyz="0.00022 0.02951 -0.0124"/>
      <mass value="2.3814"/>
      <inertia ixx="0.0058562" ixy="-1.79e-05" ixz="3.55e-06" iyy="0.0050316" iyz="-0.000888336" izz="0.003536652"/>
    </inertial>
    <visual>
      <geometry>
        <mesh filename="package://xarm_description/meshes/xarm6/visual/link1.stl"/>
      </geometry>
      <origin rpy="0 0 0" xyz="0 0 0"/>
      <material name="robot1_White"/>
    </visual>
    <collision>
      <geometry>
        <mesh filename="package://xarm_description/meshes/xarm6/visual/link1.stl"/>
      </geometry>
      <origin rpy="0 0 0" xyz="0 0 0"/>
    </collision>
  </link>
  <joint name="robot1_joint1" type="revolute">
    <parent link="robot1_link_base"/>
    <child link="robot1_link1"/>
    <origin rpy="0 0 0" xyz="0 0 0.267"/>
    <axis xyz="0 0 1"/>
    <limit effort="50.0" lower="-6.283185307179586" upper="6.283185307179586" velocity="3.14"/>
    <dynamics damping="1.0" friction="1.0"/>
  </joint>
  <link name="robot1_link2">
    <inertial>
      <origin rpy="0 0 0" xyz="0.03881 -0.22783 0.03496"/>
      <mass value="2.2675"/>
      <inertia ixx="0.028315776" ixy="0.005" ixz="0.00066546" iyy="0.0058" iyz="-0.0045741" izz="0.0273447"/>
    </inertial>
    <visual>
      <geometry>
        <mesh filename="package://xarm_description/meshes/xarm6/visual/link2.stl"/>
      </geometry>
      <origin rpy="0 0 0" xyz="0 0 0"/>
      <material name="robot1_White"/>
    </visual>
    <collision>
      <geometry>
        <mesh filename="package://xarm_description/meshes/xarm6/visual/link2.stl"/>
      </geometry>
      <origin rpy="0 0 0" xyz="0 0 0"/>
    </collision>
  </link>
  <joint name="robot1_joint2" type="revolute">
    <parent link="robot1_link1"/>
    <child link="robot1_link2"/>
    <origin rpy="-1.5708 0 0" xyz="0 0 0"/>
    <axis xyz="0 0 1"/>
    <limit effort="50.0" lower="-2.059" upper="2.0944" velocity="3.14"/>
    <dynamics damping="1.0" friction="1.0"/>
  </joint>
  <link name="robot1_link3">
    <inertial>
      <origin rpy="0 0 0" xyz="0.07041 0.11631 0.0107"/>
      <mass value="1.875"/>
      <inertia ixx="0.0063483" ixy="-0.0015397" ixz="0.00096858" iyy="0.00379758" iyz="0.00186567" izz="0.00595768"/>
    </inertial>
    <visual>
      <geometry>
        <mesh filename="package://xarm_description/meshes/xarm6/visual/link3.stl"/>
      </geometry>
      <origin rpy="0 0 0" xyz="0 0 0"/>
      <material name="robot1_White"/>
    </visual>
    <collision>
      <geometry>
        <mesh filename="package://xarm_description/meshes/xarm6/visual/link3.stl"/>
      </geometry>
      <origin rpy="0 0 0" xyz="0 0 0"/>
    </collision>
  </link>
  <joint name="robot1_joint3" type="revolute">
    <parent link="robot1_link2"/>
    <child link="robot1_link3"/>
    <origin rpy="0 0 0" xyz="0.0535 -0.2845 0"/>
    <axis xyz="0 0 1"/>
    <limit effort="32.0" lower="-3.927" upper="0.19198" velocity="3.14"/>
    <dynamics damping="1.0" friction="1.0"/>
  </joint>
  <link name="robot1_link4">
    <inertial>
      <origin rpy="0 0 0" xyz="-0.00018 0.01798 -0.02291"/>
      <mass value="1.3192"/>
      <inertia ixx="0.004896" ixy="-6.925e-06" ixz="-1.418e-05" iyy="0.00445694" iyz="-0.00023186" izz="0.00134332"/>
    </inertial>
    <visual>
      <geometry>
        <mesh filename="package://xarm_description/meshes/xarm6/visual/link4.stl"/>
      </geometry>
      <origin rpy="0 0 0" xyz="0 0 0"/>
      <material name="robot1_White"/>
    </visual>
    <collision>
      <geometry>
        <mesh filename="package://xarm_description/meshes/xarm6/visual/link4.stl"/>
      </geometry>
      <origin rpy="0 0 0" xyz="0 0 0"/>
    </collision>
  </link>
  <joint name="robot1_joint4" type="revolute">
    <parent link="robot1_link3"/>
    <child link="robot1_link4"/>
    <origin rpy="-1.5708 0 0" xyz="0.0775 0.3425 0"/>
    <axis xyz="0 0 1"/>
    <limit effort="32.0" lower="-6.283185307179586" upper="6.283185307179586" velocity="3.14"/>
    <dynamics damping="1.0" friction="1.0"/>
  </joint>
  <link name="robot1_link5">
    <inertial>
      <origin rpy="0 0 0" xyz="0.0651 0.03096 0.00315"/>
      <mass value="1.33854"/>
      <inertia ixx="0.00146378" ixy="-0.000450624" ixz="0.000284306" iyy="0.00184192" iyz="0.000130866" izz="0.002333524"/>
    </inertial>
    <visual>
      <geometry>
        <mesh filename="package://xarm_description/meshes/xarm6/visual/link5.stl"/>
      </geometry>
      <origin rpy="0 0 0" xyz="0 0 0"/>
      <material name="robot1_White"/>
    </visual>
    <collision>
      <geometry>
        <mesh filename="package://xarm_description/meshes/xarm6/visual/link5.stl"/>
      </geometry>
      <origin rpy="0 0 0" xyz="0 0 0"/>
    </collision>
  </link>
  <joint name="robot1_joint5" type="revolute">
    <parent link="robot1_link4"/>
    <child link="robot1_link5"/>
    <origin rpy="1.5708 0 0" xyz="0 0 0"/>
    <axis xyz="0 0 1"/>
    <limit effort="32.0" lower="-1.69297" upper="3.141592653589793" velocity="3.14"/>
    <dynamics damping="1.0" friction="1.0"/>
  </joint>
  <link name="robot1_link6">
    <inertial>
      <origin rpy="0 0 0" xyz="0 -0.00677 -0.01098"/>
      <mass value="0.17"/>
      <inertia ixx="9.3e-05" ixy="-0.0" ixz="-0.0" iyy="5.87e-05" iyz="-3.6e-06" izz="0.000132"/>
    </inertial>
    <visual>
      <geometry>
        <mesh filename="package://xarm_description/meshes/xarm6/visual/link6.stl"/>
      </geometry>
      <origin rpy="0 0 0" xyz="0 0 0"/>
      <material name="robot1_Silver"/>
    </visual>
    <collision>
      <geometry>
        <mesh filename="package://xarm_description/meshes/end_tool/collision/end_tool.stl"/>
      </geometry>
      <origin rpy="0 0 0" xyz="0 0 0"/>
    </collision>
  </link>
  <joint name="robot1_joint6" type="revolute">
    <parent link="robot1_link5"/>
    <child link="robot1_link6"/>
    <origin rpy="-1.5708 0 0" xyz="0.076 0.097 0"/>
    <axis xyz="0 0 1"/>
    <limit effort="20.0" lower="-6.283185307179586" upper="6.283185307179586" velocity="3.14"/>
    <dynamics damping="1.0" friction="1.0"/>
  </joint>
  <!-- <link name="${prefix}link_eef" />
    <joint name="${prefix}joint_eef" type="fixed">
      <origin xyz="0 0 0" rpy="0 0 0" />
      <parent link="${prefix}link6" />
      <child link="${prefix}link_eef" />
    </joint> -->
  <transmission name="robot1_tran1">
    <type>transmission_interface/SimpleTransmission</type>
    <joint name="robot1_joint1">
      <hardwareInterface>hardware_interface/PositionJointInterface</hardwareInterface>
    </joint>
    <actuator name="robot1_motor1">
      <hardwareInterface>hardware_interface/PositionJointInterface</hardwareInterface>
      <mechanicalReduction>100</mechanicalReduction>
    </actuator>
  </transmission>
  <transmission name="robot1_tran2">
    <type>transmission_interface/SimpleTransmission</type>
    <joint name="robot1_joint2">
      <hardwareInterface>hardware_interface/PositionJointInterface</hardwareInterface>
    </joint>
    <actuator name="robot1_motor2">
      <hardwareInterface>hardware_interface/PositionJointInterface</hardwareInterface>
      <mechanicalReduction>100</mechanicalReduction>
    </actuator>
  </transmission>
  <transmission name="robot1_tran3">
    <type>transmission_interface/SimpleTransmission</type>
    <joint name="robot1_joint3">
      <hardwareInterface>hardware_interface/PositionJointInterface</hardwareInterface>
    </joint>
    <actuator name="robot1_motor3">
      <hardwareInterface>hardware_interface/PositionJointInterface</hardwareInterface>
      <mechanicalReduction>100</mechanicalReduction>
    </actuator>
  </transmission>
  <transmission name="robot1_tran4">
    <type>transmission_interface/SimpleTransmission</type>
    <joint name="robot1_joint4">
      <hardwareInterface>hardware_interface/PositionJointInterface</hardwareInterface>
    </joint>
    <actuator name="robot1_motor4">
      <hardwareInterface>hardware_interface/PositionJointInterface</hardwareInterface>
      <mechanicalReduction>100</mechanicalReduction>
    </actuator>
  </transmission>
  <transmission name="robot1_tran5">
    <type>transmission_interface/SimpleTransmission</type>
    <joint name="robot1_joint5">
      <hardwareInterface>hardware_interface/PositionJointInterface</hardwareInterface>
    </joint>
    <actuator name="robot1_motor5">
      <hardwareInterface>hardware_interface/PositionJointInterface</hardwareInterface>
      <mechanicalReduction>100</mechanicalReduction>
    </actuator>
  </transmission>
  <transmission name="robot1_tran6">
    <type>transmission_interface/SimpleTransmission</type>
    <joint name="robot1_joint6">
      <hardwareInterface>hardware_interface/PositionJointInterface</hardwareInterface>
    </joint>
    <actuator name="robot1_motor6">
      <hardwareInterface>hardware_interface/PositionJointInterface</hardwareInterface>
      <mechanicalReduction>100</mechanicalReduction>
    </actuator>
  </transmission>
  <gazebo reference="robot1_link_base">
    <selfCollide>true</selfCollide>
  </gazebo>
  <gazebo reference="robot1_link1">
    <selfCollide>true</selfCollide>
  </gazebo>
  <gazebo reference="robot1_link2">
    <selfCollide>true</selfCollide>
  </gazebo>
  <gazebo reference="robot1_link3">
    <selfCollide>true</selfCollide>
  </gazebo>
  <gazebo reference="robot1_link4">
    <selfCollide>true</selfCollide>
  </gazebo>
  <gazebo reference="robot1_link5">
    <selfCollide>true</selfCollide>
  </gazebo>
  <gazebo reference="robot1_link6">
    <selfCollide>true</selfCollide>
  </gazebo>
  <link name="robot1_link_eef"/>
  <joint name="robot1_joint_eef" type="fixed">
    <origin rpy="0 0 0" xyz="0 0 0"/>
    <parent link="robot1_link6"/>
    <child link="robot1_link_eef"/>
  </joint>
  <gazebo>
    <plugin filename="libgazebo_ros2_control.so" name="gazebo_ros2_control">
      <robot_sim_type>gazebo_ros2_control/GazeboSystem</robot_sim_type>
      <parameters>/home/gerard/ros_industrial_ws/install/xarm_controller/share/xarm_controller/config/xarm6_controllers.yaml</parameters>
    </plugin>
  </gazebo>
  <!-- Insert at the end of xarm_device_macro.xacro -->
  <link name="robot1_xarm_link"/>
  <!-- Vacuum Gripper1 -->
  <!--
  <xacro:include filename="$(find ros_industrial_support)/urdf/vacuum_gripper/vacuum_gripper.urdf.xacro"/>
  <xacro:vacuum_gripper_urdf prefix="vacuum_gripper1_" joint_prefix="vacuum_gripper1_joint"/>
-->
  <!-- link list -->
  <link name="bin_1_base_link">
    <visual>
      <origin rpy="0 0 0" xyz="0 0 0"/>
      <geometry>
        <mesh filename="package://ros_industrial_support/meshes/bin/visual/bin.dae"/>
        <scale>0.6 0.6 0.6</scale>
      </geometry>
    </visual>
    <collision>
      <origin rpy="0 0 0" xyz="0 0 0"/>
      <geometry>
        <mesh filename="package://ros_industrial_support/meshes/bin/collision/bin_bottom.dae"/>
        <scale>0.6 0.6 0.6</scale>
      </geometry>
    </collision>
    <collision>
      <origin rpy="0 0 0" xyz="0 0 0"/>
      <geometry>
        <mesh filename="package://ros_industrial_support/meshes/bin/collision/bin_sides.dae"/>
        <scale>0.6 0.6 0.6</scale>
      </geometry>
    </collision>
    <inertial>
      <origin rpy="0 0 0" xyz="0 0 0"/>
      <inertia ixx="1.0" ixy="0" ixz="0" iyy="1.0" iyz="0" izz="1.0"/>
      <mass value="100"/>
    </inertial>
  </link>
  <link name="bin_1_drop_point">
    <inertial>
      <origin rpy="0 0 0" xyz="0 0 0"/>
      <inertia ixx="1.0" ixy="0" ixz="0" iyy="1.0" iyz="0" izz="1.0"/>
      <mass value="1.0"/>
    </inertial>
  </link>
  <!-- joint list -->
  <joint name="bin_1_joint_1" type="fixed">
    <origin rpy="0 0 0" xyz="0 0 1.0"/>
    <parent link="bin_1_base_link"/>
    <child link="bin_1_drop_point"/>
  </joint>
  <!-- Joints -->
  <joint name="world_interface_to_world" type="fixed">
    <parent link="world"/>
    <child link="world_interface"/>
  </joint>
  <!-- robot1-pedestal to world. -->
  <joint name="robot1_pedestal_to_world_interface" type="fixed">
    <parent link="world_interface"/>
    <child link="robot1_pedestal_link"/>
    <origin rpy="0.0 0.0 0.0" xyz="0.5 1.8 0.0"/>
  </joint>
  <!-- robot1 to pedestal. -->
  <joint name="robot1_to_pedestal" type="fixed">
    <origin rpy="0 0 1.5707963267948966" xyz="0 0 0.95"/>
    <parent link="robot1_pedestal_link"/>
    <child link="robot1_xarm_link"/>
  </joint>
  <!-- gripper1 to robot1. -->
  <!--
  <joint name="gripper1_to_robot1" type="fixed">
    <parent link="robot1_tool0" />
    <child link="vacuum_gripper1_base_link" />
  </joint>
-->
  <!-- bin 1 -->
  <joint name="bin_1_joint" type="fixed">
    <parent link="world_interface"/>
    <child link="bin_1_base_link"/>
    <origin rpy="0 0 0" xyz="-8.0 -2.2 0"/>
  </joint>
  <link name="robot2_pedestal_link">
    <visual>
      <origin xyz="0 0 0.3"/>
      <geometry>
        <box size="0.3 0.3 0.6"/>
      </geometry>
      <material name="robot2_pedestal_color">
        <color rgba="0 0.1568627450980392 0.5254901960784314 1"/>
      </material>
    </visual>
  </link>
  <joint name="robot2_pedestal_joint" type="fixed">
    <origin xyz="-7.8 -1.5 0"/>
    <parent link="world"/>
    <child link="robot2_pedestal_link"/>
  </joint>
  <!-- links: main serial chain -->
  <link name="robot2_base_link">
    <visual>
      <origin rpy="0 0 0" xyz="0 0 0"/>
      <geometry>
        <mesh filename="package://urdf_basics/meshes/lrmate200ic/collision/base_link.stl"/>
      </geometry>
      <material name="">
        <color rgba="0.23921568627450981 0.23921568627450981 0.23921568627450981 1.0"/>
      </material>
    </visual>
    <collision>
      <origin rpy="0 0 0" xyz="0 0 0"/>
      <geometry>
        <mesh filename="package://urdf_basics/meshes/lrmate200ic/collision/base_link.stl"/>
      </geometry>
    </collision>
  </link>
  <link name="robot2_link_1">
    <visual>
      <origin rpy="0 0 0" xyz="0 0 0"/>
      <geometry>
        <mesh filename="package://urdf_basics/meshes/lrmate200ic/collision/link_1.stl"/>
      </geometry>
      <material name="">
        <color rgba="0.96 0.76 0.13 1.0"/>
      </material>
    </visual>
    <collision>
      <origin rpy="0 0 0" xyz="0 0 0"/>
      <geometry>
        <mesh filename="package://urdf_basics/meshes/lrmate200ic/collision/link_1.stl"/>
      </geometry>
    </collision>
  </link>
  <link name="robot2_link_2">
    <visual>
      <origin rpy="0 0 0" xyz="0 0 0"/>
      <geometry>
        <mesh filename="package://urdf_basics/meshes/lrmate200ic/collision/link_2.stl"/>
      </geometry>
      <material name="">
        <color rgba="0.96 0.76 0.13 1.0"/>
      </material>
    </visual>
    <collision>
      <origin rpy="0 0 0" xyz="0 0 0"/>
      <geometry>
        <mesh filename="package://urdf_basics/meshes/lrmate200ic/collision/link_2.stl"/>
      </geometry>
    </collision>
  </link>
  <link name="robot2_link_3">
    <visual>
      <origin rpy="0 0 0" xyz="0 0 0"/>
      <geometry>
        <mesh filename="package://urdf_basics/meshes/lrmate200ic/collision/link_3.stl"/>
      </geometry>
      <material name="">
        <color rgba="0.96 0.76 0.13 1.0"/>
      </material>
    </visual>
    <collision>
      <origin rpy="0 0 0" xyz="0 0 0"/>
      <geometry>
        <mesh filename="package://urdf_basics/meshes/lrmate200ic/collision/link_3.stl"/>
      </geometry>
    </collision>
  </link>
  <link name="robot2_link_4">
    <visual>
      <origin rpy="0 0 0" xyz="0 0 0"/>
      <geometry>
        <mesh filename="package://urdf_basics/meshes/lrmate200ic/collision/link_4.stl"/>
      </geometry>
      <material name="">
        <color rgba="0.96 0.76 0.13 1.0"/>
      </material>
    </visual>
    <collision>
      <origin rpy="0 0 0" xyz="0 0 0"/>
      <geometry>
        <mesh filename="package://urdf_basics/meshes/lrmate200ic/collision/link_4.stl"/>
      </geometry>
    </collision>
  </link>
  <link name="robot2_link_5">
    <visual>
      <origin rpy="0 0 0" xyz="0 0 0"/>
      <geometry>
        <mesh filename="package://urdf_basics/meshes/lrmate200ic/collision/link_5.stl"/>
      </geometry>
      <material name="">
        <color rgba="0.96 0.76 0.13 1.0"/>
      </material>
    </visual>
    <collision>
      <origin rpy="0 0 0" xyz="0 0 0"/>
      <geometry>
        <mesh filename="package://urdf_basics/meshes/lrmate200ic/collision/link_5.stl"/>
      </geometry>
    </collision>
  </link>
  <link name="robot2_link_6">
    <visual>
      <origin rpy="0 0 0" xyz="0 0 0"/>
      <geometry>
        <mesh filename="package://urdf_basics/meshes/lrmate200ic/collision/link_6.stl"/>
      </geometry>
      <material name="">
        <color rgba="0.15 0.15 0.15 1.0"/>
      </material>
    </visual>
    <collision>
      <origin rpy="0 0 0" xyz="0 0 0"/>
      <geometry>
        <mesh filename="package://urdf_basics/meshes/lrmate200ic/collision/link_6.stl"/>
      </geometry>
    </collision>
  </link>
  <!-- joints: main serial chain -->
  <joint name="robot2_joint_1" type="revolute">
    <origin rpy="0 0 0" xyz="0 0 0.330"/>
    <parent link="robot2_base_link"/>
    <child link="robot2_link_1"/>
    <axis xyz="0 0 1"/>
    <limit effort="0" lower="-2.9671" upper="2.9671" velocity="6.1087"/>
  </joint>
  <joint name="robot2_joint_2" type="revolute">
    <origin rpy="0 0 0" xyz="0.075 0 0"/>
    <parent link="robot2_link_1"/>
    <child link="robot2_link_2"/>
    <axis xyz="0 1 0"/>
    <limit effort="0" lower="-1.0472" upper="2.4435" velocity="6.1087"/>
  </joint>
  <joint name="robot2_joint_3" type="revolute">
    <origin rpy="0 0 0" xyz="0 0 0.300"/>
    <parent link="robot2_link_2"/>
    <child link="robot2_link_3"/>
    <axis xyz="0 -1 0"/>
    <limit effort="0" lower="-2.4784" upper="4.0143" velocity="6.9813"/>
  </joint>
  <joint name="robot2_joint_4" type="revolute">
    <origin rpy="0 0 0" xyz="0 0 0.075"/>
    <parent link="robot2_link_3"/>
    <child link="robot2_link_4"/>
    <axis xyz="-1 0 0"/>
    <limit effort="0" lower="-3.3161" upper="3.3161" velocity="7.8540"/>
  </joint>
  <joint name="robot2_joint_5" type="revolute">
    <origin rpy="0 0 0" xyz="0.320 0 0"/>
    <parent link="robot2_link_4"/>
    <child link="robot2_link_5"/>
    <axis xyz="0 -1 0"/>
    <limit effort="0" lower="-2.0944" upper="2.0944" velocity="7.8540"/>
  </joint>
  <joint name="robot2_joint_6" type="revolute">
    <origin rpy="0 0 0" xyz="0.080 0 0"/>
    <parent link="robot2_link_5"/>
    <child link="robot2_link_6"/>
    <axis xyz="-1 0 0"/>
    <limit effort="0" lower="-6.2832" upper="6.2832" velocity="12.5664"/>
  </joint>
  <!-- ROS-Industrial 'base' frame: base_link to Fanuc World Coordinates transform -->
  <link name="robot2_base"/>
  <joint name="robot2_base_link-base" type="fixed">
    <origin rpy="0 0 0" xyz="0 0 0.330"/>
    <parent link="robot2_base_link"/>
    <child link="robot2_base"/>
  </joint>
  <!-- ROS-Industrial 'flange' frame: attachment point for EEF models -->
  <link name="robot2_flange"/>
  <joint name="robot2_joint_6-flange" type="fixed">
    <origin rpy="0 0 0" xyz="0 0 0"/>
    <parent link="robot2_link_6"/>
    <child link="robot2_flange"/>
  </joint>
  <!-- ROS-Industrial 'tool0' frame: all-zeros tool frame -->
  <link name="robot2_tool0"/>
  <joint name="robot2_link_6-tool0" type="fixed">
    <origin rpy="3.141592653589793 -1.5707963267948966 0" xyz="0 0 0"/>
    <parent link="robot2_link_6"/>
    <child link="robot2_tool0"/>
  </joint>
  <joint name="robot2_robot2_pedestal_joint" type="fixed">
    <parent link="robot2_pedestal_link"/>
    <child link="robot2_base_link"/>
    <!--
    <origin xyz="0 0 0.60" rpy="0 0 ${radians(180)}" />
    -->
    <origin rpy="0 0 0" xyz="0 0 0.60"/>
  </joint>
</robot>
